# 使用do-catch语句处理throws函数

在Swift中，错误处理是一个重要的概念，尤其是在进行网络请求时。使用`do-catch`语句可以有效地捕获和处理可能发生的错误。以下是如何使用`do-catch`语句处理`throws`函数的详细步骤。

## 1. 定义可能抛出错误的函数

首先，你需要定义一个可能会抛出错误的函数。使用`throws`关键字来标记这个函数。例如：

```swift
func fetchData(from url: String) throws -> Data {
    guard let url = URL(string: url) else {
        throw URLError(.badURL)
    }
    return try Data(contentsOf: url)
}
```

在这个例子中，如果URL无效，将抛出一个`URLError`。

## 2. 使用do-catch语句调用函数

接下来，使用`do-catch`语句来调用这个函数并处理可能的错误。示例如下：

```swift
do {
    let data = try fetchData(from: "https://example.com/data")
    // 处理获取到的数据
} catch {
    print("发生错误: \(error)")
}
```

在`do`块中，你可以尝试调用可能抛出错误的函数。如果发生错误，控制权将转移到`catch`块，在这里你可以处理错误。

## 3. 捕获特定错误

你还可以捕获特定类型的错误，以便进行更精确的错误处理。例如：

```swift
do {
    let data = try fetchData(from: "https://example.com/data")
    // 处理获取到的数据
} catch let error as URLError {
    print("URL错误: \(error)")
} catch {
    print("发生其他错误: \(error)")
}
```

在这个例子中，`catch let error as URLError`将捕获`URLError`类型的错误，而其他类型的错误将被捕获在最后一个`catch`中。

## 4. 使用throw语句重新抛出错误

在某些情况下，你可能希望在处理错误后重新抛出它。可以使用`throw`语句来实现。例如：

```swift
func processData() throws {
    do {
        let data = try fetchData(from: "https://example.com/data")
        // 处理数据
    } catch {
        // 记录错误
        print("处理数据时发生错误: \(error)")
        throw error // 重新抛出错误
    }
}
```

这样，调用`processData`的地方可以继续处理这个错误。

## 总结

使用`do-catch`语句处理`throws`函数是Swift中错误处理的核心。通过这种方式，你可以优雅地捕获和处理错误，确保应用程序的稳定性和用户体验。记住，良好的错误处理不仅能提高代码的可读性，还能帮助你快速定位和解决问题。💪✨